import { Either, EitherIO, ErrorFn } from '../src';

describe('Testing EitherIO Monad', () => {
  const rightValue: number = 42;
  const errorMessage: string = 'You shall not pass';
  let eitherIO: EitherIO<string, number>;
  let eitherFailIO: EitherIO<string, number>;

  beforeAll(() => {
    eitherIO = EitherIO.of(() => errorMessage, rightValue);
    eitherFailIO = EitherIO.raise(() => errorMessage);
  });

  it('Creating a successful EitherIO, should keep value when unsafeRun', async () => {
    const value: number = await eitherIO.unsafeRun();
    expect(value).toEqual(rightValue);
  });

  it('Creating successful EitherIO from Promise should keep value when unsafeRun', async () => {
    const anotherIO: EitherIO<string, number> = EitherIO.from(
      () => errorMessage,
      async () => rightValue,
    );
    await expect(anotherIO.unsafeRun()).resolves.toEqual(rightValue);
  });

  it('Creating a failure EitherIO from Promise should show error when unsafeRun', async () => {
    const anotherIO: EitherIO<string, number> = EitherIO.from(
      () => errorMessage,
      async () => {
        throw new Error('error');
      },
    );
    await expect(anotherIO.unsafeRun()).rejects.toEqual(errorMessage);
  });

  it('Creating EitherIO from right Either should show value when unsafeRun', async () => {
    const either: Either<string, number> = Either.right(42);
    const eitherIO: EitherIO<string, number> = EitherIO.fromEither(
      () => errorMessage,
      () => either,
    );
    await expect(eitherIO.unsafeRun()).resolves.toEqual(42);
  });

  it('Creating EitherIO from left Either should show error when unsafeRun', async () => {
    const either: Either<string, number> = Either.left(errorMessage);
    const eitherIO: EitherIO<string, number> = EitherIO.fromEither(
      () => 'Another one?',
      () => either,
    );
    await expect(eitherIO.unsafeRun()).rejects.toEqual(errorMessage);
  });

  it('Creating a failure EitherIO should raise error when unsafeRun', async () => {
    await expect(eitherFailIO.unsafeRun()).rejects.toEqual(errorMessage);
  });

  it('Flat mapping a successful EitherIO should change the content', async () => {
    const nextIO: EitherIO<string, string> = eitherIO.flatMap((value: number, errorFn: ErrorFn<string>) =>
      EitherIO.of(errorFn, String(value)),
    );
    await expect(nextIO.unsafeRun()).resolves.toEqual(String(rightValue));
  });

  it('Flat mapping a failed EitherIO and unsafe running it should raise error', async () => {
    const nextIO: EitherIO<string, string> = eitherFailIO.flatMap((value: number, errorFn: ErrorFn<string>) =>
      EitherIO.of(errorFn, String(value)),
    );
    await expect(nextIO.unsafeRun()).rejects.toEqual(errorMessage);
  });

  it('Mapping a successful EitherIO should change the content', async () => {
    const nextIO: EitherIO<string, string> = eitherIO.map((value: number) => String(value));
    await expect(nextIO.unsafeRun()).resolves.toEqual(String(rightValue));
  });

  it('Mapping a failed EitherIO and unsafe running it should raise error', async () => {
    const nextIO: EitherIO<string, string> = eitherFailIO.map((value: number) => String(value));
    await expect(nextIO.unsafeRun()).rejects.toEqual(errorMessage);
  });

  it('Tapping a successful EitherIO should not change the content', async () => {
    const value: number = await eitherIO.tap((value: number) => value).unsafeRun();
    expect(value).toEqual(rightValue);
  });

  it('Tapping a failed EitherIO and unsafe runnning it should raise error', async () => {
    const nextIO: EitherIO<string, number> = eitherFailIO.tap((value: number) => value);
    await expect(nextIO.unsafeRun()).rejects.toEqual(errorMessage);
  });

  it("Filtering a successful EitherIO with valid condition should keep IO's value", async () => {
    const nextIO: EitherIO<string, number> = eitherIO.filter(
      () => 'Another one?',
      (value: number) => value === rightValue,
    );
    await expect(nextIO.unsafeRun()).resolves.toEqual(rightValue);
  });

  it('Filtering a successful EitherIO with invalid condition should raise error', async () => {
    const nextErrorMessage: string = 'Another one?';
    const nextIO: EitherIO<string, number> = eitherIO.filter(
      () => nextErrorMessage,
      (value: number) => value !== rightValue,
    );
    await expect(nextIO.unsafeRun()).rejects.toEqual(nextErrorMessage);
  });

  it('Filtering a failed EitherIO with valid condition should raise previous error', async () => {
    const nextErrorMessage: string = 'Another one?';
    const nextIO: EitherIO<string, number> = eitherFailIO.filter(
      () => nextErrorMessage,
      (value: number) => value === rightValue,
    );
    await expect(nextIO.unsafeRun()).rejects.toEqual(errorMessage);
  });

  it('Filtering a failed EitherIO with invalid condition should raise previous error', async () => {
    const nextErrorMessage: string = 'Another one?';
    const nextIO: EitherIO<string, number> = eitherFailIO.filter(
      () => nextErrorMessage,
      (value: number) => value !== rightValue,
    );
    await expect(nextIO.unsafeRun()).rejects.toEqual(errorMessage);
  });

  it('Zipping a successful EitherIO with another successful IO should merge values', async () => {
    const anotherIO: EitherIO<string, number> = EitherIO.of(() => errorMessage, 10);
    const nextIO: EitherIO<string, number> = eitherIO.zip(
      anotherIO,
      (value1: number, value2: number) => value1 + value2,
    );
    await expect(nextIO.unsafeRun()).resolves.toEqual(52);
  });

  it('Zipping a successful EitherIO with a failed IO should raise error', async () => {
    const nextIO: EitherIO<string, number> = eitherIO.zip(
      eitherFailIO,
      (value1: number, value2: number) => value1 + value2,
    );
    await expect(nextIO.unsafeRun()).rejects.toEqual(errorMessage);
  });

  it('Zipping a failed EitherIO with a successful IO should raise error', async () => {
    const nextIO: EitherIO<string, number> = eitherFailIO.zip(
      eitherIO,
      (value1: number, value2: number) => value1 + value2,
    );
    await expect(nextIO.unsafeRun()).rejects.toEqual(errorMessage);
  });

  it('Zipping a failed EitherIO with a another failed IO should raise first IO error', async () => {
    const anotherErrorMessage: string = 'Another one?';
    const anotherIO: EitherIO<string, number> = EitherIO.raise(() => anotherErrorMessage);
    const nextIO: EitherIO<string, number> = eitherFailIO.zip(
      anotherIO,
      (value1: number, value2: number) => value1 + value2,
    );
    const nextIO2: EitherIO<string, number> = anotherIO.zip(
      eitherFailIO,
      (value1: number, value2: number) => value1 + value2,
    );
    await expect(nextIO.unsafeRun()).rejects.toEqual(errorMessage);
    await expect(nextIO2.unsafeRun()).rejects.toEqual(anotherErrorMessage);
  });

  it('Flat left mapping a successful EitherIO should not change the content', async () => {
    const nextIO: EitherIO<boolean, number> = eitherIO.flatMapLeft(
      () => false,
      () => EitherIO.raise(() => true),
    );
    await expect(nextIO.unsafeRun()).resolves.toEqual(rightValue);
  });

  it('Flat left mapping a failed EitherIO should change left content', async () => {
    const nextIO: EitherIO<boolean, number> = eitherFailIO.flatMapLeft(
      () => false,
      () => EitherIO.raise(() => true),
    );
    await expect(nextIO.unsafeRun()).rejects.toEqual(true);
  });

  it('Left mapping a successful EitherIO should not change the content', async () => {
    const nextIO: EitherIO<boolean, number> = eitherIO.mapLeft(
      () => false,
      () => true,
    );
    await expect(nextIO.unsafeRun()).resolves.toEqual(rightValue);
  });

  it('Left mapping a failed EitherIO should change left content', async () => {
    const nextIO: EitherIO<boolean, number> = eitherFailIO.mapLeft(
      () => false,
      () => true,
    );
    await expect(nextIO.unsafeRun()).rejects.toEqual(true);
  });

  it("Catch a successful EitherIO should keep EitherIO's value", async () => {
    const value: number = await eitherIO.catch(() => Either.right(52)).unsafeRun();
    expect(value).toEqual(rightValue);
  });

  it('Catch a failed EitherIO should map left content to new value', async () => {
    const value: number = await eitherFailIO.catch(() => Either.right(52)).unsafeRun();
    expect(value).toEqual(52);
  });

  it('Catch a failed EitherIO should map left content to new value', async () => {
    const either: Either<string | Error, number> = await eitherFailIO
      .catch(() => {
        throw new Error('error');
      })
      .safeRun();
    expect(either.getRight).toThrow('No right value found');
    expect(either.getLeft()).toEqual(errorMessage);
  });

  it('Safe run successful EitherIO should return Either Right', async () => {
    const either: Either<string | Error, number> = await eitherIO.safeRun();
    expect(either.getRight()).toEqual(rightValue);
    expect(either.getLeft).toThrow('No left value found');
  });

  it('Safe run failed IO should return Either Left', async () => {
    const either: Either<string | Error, number> = await eitherFailIO.safeRun();
    expect(either.getRight).toThrow('No right value found');
    expect(either.getLeft()).toEqual(errorMessage);
  });

  it('Creating EitherIO from Either but using throwable promise should return Either Left', async () => {
    const eitherIO: EitherIO<string, number> = EitherIO.fromEither(
      () => errorMessage,
      async () => {
        throw new Error('error');
      },
    );
    const either: Either<string | Error, number> = await eitherIO.safeRun();
    expect(either.getRight).toThrow('No right value found');
    expect(either.getLeft()).toEqual(errorMessage);
  });

  it('Throwing inside error handler should not break EitherIO', async () => {
    const nextErrorMessage: string = errorMessage + ' 2';
    const eitherIO: EitherIO<string, number> = EitherIO.from(
      () => {
        throw new Error(errorMessage);
      },
      () => {
        throw new Error('Throw inside start handler');
      },
      // eslint-disable-next-line @typescript-eslint/ban-ts-comment
      /** @ts-ignore */
    ).catch((error: never) => {
      expect(error).toEqual(new Error(`Critical error! Does not throw an exception inside the error handler!`));
      return Either.left(nextErrorMessage);
    });

    const either: Either<string | Error, number> = await eitherIO.safeRun();
    expect(either.getRight).toThrow('No right value found');
    expect(either.getLeft()).toEqual(nextErrorMessage);
  });

  it('Throwing inside error handler should be recoverable', async () => {
    const eitherIO: EitherIO<string, number> = EitherIO.from(
      () => {
        throw new Error(errorMessage);
      },
      () => {
        throw new Error('Throw inside start handler');
      },
      // eslint-disable-next-line @typescript-eslint/ban-ts-comment
      /** @ts-ignore */
    ).catch((error: never) => {
      expect(error).toEqual(new Error(`Critical error! Does not throw an exception inside the error handler!`));
      return Either.right(42);
    });

    const either: Either<string | Error, number> = await eitherIO.safeRun();
    expect(either.getLeft).toThrow('No left value found');
    expect(either.getRight()).toEqual(42);
  });

  it('Check if EitherIO operators run properly', async () => {
    let message: string = '';
    const anotherFailIO: EitherIO<string, number> = eitherIO
      .map((value: number) => {
        message = message + 'u';
        return value * 10;
      })
      .flatMap(() => {
        message = message + 's';
        throw new Error('error');
      });
    const result: Either<string | Error, number> = await eitherIO
      .flatMap((value: number, errorFn: ErrorFn<string>) => {
        message = message + 'm';
        return EitherIO.of(errorFn, value / 2);
      })
      .flatMap((value: number) => {
        message = message + 'y';
        return EitherIO.raise(() => value.toString());
      })
      .map((value: number) => {
        message = message + '0';
        return value / 2;
      })
      .catch(() => {
        message = message + ' ';
        return Either.right(42);
      })
      .map((value: number) => {
        message = message + 'p';
        return value / 2;
      })
      .tap(() => {
        message = message + 'r';
      })
      .filter(
        () => 'error',
        (value: number) => {
          message = message + 'e';
          return value < 0;
        },
      )
      .map((value: number) => {
        message = message + '1';
        return value * 2;
      })
      .flatMap((value: number, errorFn: ErrorFn<string>) => {
        message = message + '2';
        return EitherIO.of(errorFn, value / 2);
      })
      .catch(() => {
        message = message + 'c';
        return Either.right(42);
      })
      .filter(
        () => 'error',
        async (value: number) => {
          message = message + 'i';
          return value > 0;
        },
      )
      .zip(eitherIO, (value1: number, value2: number) => {
        message = message + 'o';
        return value1 / 2 + value2 / 2;
      })
      .zip(anotherFailIO, (value1: number, value2: number) => {
        message = message + '3';
        return value1 / 2 + value2 / 2;
      })
      .catch(() => {
        message = message + '!';
        return Either.right(42);
      })
      .safeRun();

    expect(result.getRight()).toEqual(42);
    expect(message).toEqual('my precious!');
  });
});
